[2022-04-18 22:48:32] ERROR|django.request|Internal Server Error: /api/user-register/
Traceback (most recent call last):
  File "/home/preetham/.local/lib/python3.8/site-packages/django/db/backends/utils.py", line 89, in _execute
    return self.cursor.execute(sql, params)
  File "/home/preetham/.local/lib/python3.8/site-packages/django/db/backends/mysql/base.py", line 75, in execute
    return self.cursor.execute(query, args)
  File "/home/preetham/.local/lib/python3.8/site-packages/MySQLdb/cursors.py", line 206, in execute
    res = self._query(query)
  File "/home/preetham/.local/lib/python3.8/site-packages/MySQLdb/cursors.py", line 319, in _query
    db.query(q)
  File "/home/preetham/.local/lib/python3.8/site-packages/MySQLdb/connections.py", line 254, in query
    _mysql.connection.query(self, query)
MySQLdb._exceptions.ProgrammingError: (1146, "Table 'tododb.api_user' doesn't exist")

The above exception was the direct cause of the following exception:

Traceback (most recent call last):
  File "/home/preetham/.local/lib/python3.8/site-packages/django/core/handlers/exception.py", line 55, in inner
    response = get_response(request)
  File "/home/preetham/.local/lib/python3.8/site-packages/django/core/handlers/base.py", line 197, in _get_response
    response = wrapped_callback(request, *callback_args, **callback_kwargs)
  File "/home/preetham/.local/lib/python3.8/site-packages/django/views/decorators/csrf.py", line 54, in wrapped_view
    return view_func(*args, **kwargs)
  File "/home/preetham/.local/lib/python3.8/site-packages/django/views/generic/base.py", line 84, in view
    return self.dispatch(request, *args, **kwargs)
  File "/home/preetham/.local/lib/python3.8/site-packages/rest_framework/views.py", line 505, in dispatch
    response = self.handle_exception(exc)
  File "/home/preetham/.local/lib/python3.8/site-packages/rest_framework/views.py", line 465, in handle_exception
    self.raise_uncaught_exception(exc)
  File "/home/preetham/.local/lib/python3.8/site-packages/rest_framework/views.py", line 476, in raise_uncaught_exception
    raise exc
  File "/home/preetham/.local/lib/python3.8/site-packages/rest_framework/views.py", line 502, in dispatch
    response = handler(request, *args, **kwargs)
  File "/home/preetham/.local/lib/python3.8/site-packages/rest_framework/decorators.py", line 50, in handler
    return func(*args, **kwargs)
  File "/home/preetham/SAD-Final/todoapp/api/views.py", line 60, in user_register
    if serializer.is_valid():
  File "/home/preetham/.local/lib/python3.8/site-packages/rest_framework/serializers.py", line 234, in is_valid
    self._validated_data = self.run_validation(self.initial_data)
  File "/home/preetham/.local/lib/python3.8/site-packages/rest_framework/serializers.py", line 433, in run_validation
    value = self.to_internal_value(data)
  File "/home/preetham/.local/lib/python3.8/site-packages/rest_framework/serializers.py", line 490, in to_internal_value
    validated_value = field.run_validation(primitive_value)
  File "/home/preetham/.local/lib/python3.8/site-packages/rest_framework/fields.py", line 830, in run_validation
    return super().run_validation(data)
  File "/home/preetham/.local/lib/python3.8/site-packages/rest_framework/fields.py", line 566, in run_validation
    self.run_validators(value)
  File "/home/preetham/.local/lib/python3.8/site-packages/rest_framework/fields.py", line 588, in run_validators
    validator(value, self)
  File "/home/preetham/.local/lib/python3.8/site-packages/rest_framework/validators.py", line 73, in __call__
    if qs_exists(queryset):
  File "/home/preetham/.local/lib/python3.8/site-packages/rest_framework/validators.py", line 21, in qs_exists
    return queryset.exists()
  File "/home/preetham/.local/lib/python3.8/site-packages/django/db/models/query.py", line 892, in exists
    return self.query.has_results(using=self.db)
  File "/home/preetham/.local/lib/python3.8/site-packages/django/db/models/sql/query.py", line 589, in has_results
    return compiler.has_results()
  File "/home/preetham/.local/lib/python3.8/site-packages/django/db/models/sql/compiler.py", line 1329, in has_results
    return bool(self.execute_sql(SINGLE))
  File "/home/preetham/.local/lib/python3.8/site-packages/django/db/models/sql/compiler.py", line 1361, in execute_sql
    cursor.execute(sql, params)
  File "/home/preetham/.local/lib/python3.8/site-packages/django/db/backends/utils.py", line 103, in execute
    return super().execute(sql, params)
  File "/home/preetham/.local/lib/python3.8/site-packages/django/db/backends/utils.py", line 67, in execute
    return self._execute_with_wrappers(
  File "/home/preetham/.local/lib/python3.8/site-packages/django/db/backends/utils.py", line 80, in _execute_with_wrappers
    return executor(sql, params, many, context)
  File "/home/preetham/.local/lib/python3.8/site-packages/django/db/backends/utils.py", line 89, in _execute
    return self.cursor.execute(sql, params)
  File "/home/preetham/.local/lib/python3.8/site-packages/django/db/utils.py", line 91, in __exit__
    raise dj_exc_value.with_traceback(traceback) from exc_value
  File "/home/preetham/.local/lib/python3.8/site-packages/django/db/backends/utils.py", line 89, in _execute
    return self.cursor.execute(sql, params)
  File "/home/preetham/.local/lib/python3.8/site-packages/django/db/backends/mysql/base.py", line 75, in execute
    return self.cursor.execute(query, args)
  File "/home/preetham/.local/lib/python3.8/site-packages/MySQLdb/cursors.py", line 206, in execute
    res = self._query(query)
  File "/home/preetham/.local/lib/python3.8/site-packages/MySQLdb/cursors.py", line 319, in _query
    db.query(q)
  File "/home/preetham/.local/lib/python3.8/site-packages/MySQLdb/connections.py", line 254, in query
    _mysql.connection.query(self, query)
django.db.utils.ProgrammingError: (1146, "Table 'tododb.api_user' doesn't exist")
[2022-04-18 22:48:32] ERROR|django.request|Internal Server Error: /api/user-register/
Traceback (most recent call last):
  File "/home/preetham/.local/lib/python3.8/site-packages/django/db/backends/utils.py", line 89, in _execute
    return self.cursor.execute(sql, params)
  File "/home/preetham/.local/lib/python3.8/site-packages/django/db/backends/mysql/base.py", line 75, in execute
    return self.cursor.execute(query, args)
  File "/home/preetham/.local/lib/python3.8/site-packages/MySQLdb/cursors.py", line 206, in execute
    res = self._query(query)
  File "/home/preetham/.local/lib/python3.8/site-packages/MySQLdb/cursors.py", line 319, in _query
    db.query(q)
  File "/home/preetham/.local/lib/python3.8/site-packages/MySQLdb/connections.py", line 254, in query
    _mysql.connection.query(self, query)
MySQLdb._exceptions.ProgrammingError: (1146, "Table 'tododb.api_user' doesn't exist")

The above exception was the direct cause of the following exception:

Traceback (most recent call last):
  File "/home/preetham/.local/lib/python3.8/site-packages/django/core/handlers/exception.py", line 55, in inner
    response = get_response(request)
  File "/home/preetham/.local/lib/python3.8/site-packages/django/core/handlers/base.py", line 197, in _get_response
    response = wrapped_callback(request, *callback_args, **callback_kwargs)
  File "/home/preetham/.local/lib/python3.8/site-packages/django/views/decorators/csrf.py", line 54, in wrapped_view
    return view_func(*args, **kwargs)
  File "/home/preetham/.local/lib/python3.8/site-packages/django/views/generic/base.py", line 84, in view
    return self.dispatch(request, *args, **kwargs)
  File "/home/preetham/.local/lib/python3.8/site-packages/rest_framework/views.py", line 505, in dispatch
    response = self.handle_exception(exc)
  File "/home/preetham/.local/lib/python3.8/site-packages/rest_framework/views.py", line 465, in handle_exception
    self.raise_uncaught_exception(exc)
  File "/home/preetham/.local/lib/python3.8/site-packages/rest_framework/views.py", line 476, in raise_uncaught_exception
    raise exc
  File "/home/preetham/.local/lib/python3.8/site-packages/rest_framework/views.py", line 502, in dispatch
    response = handler(request, *args, **kwargs)
  File "/home/preetham/.local/lib/python3.8/site-packages/rest_framework/decorators.py", line 50, in handler
    return func(*args, **kwargs)
  File "/home/preetham/SAD-Final/todoapp/api/views.py", line 60, in user_register
    if serializer.is_valid():
  File "/home/preetham/.local/lib/python3.8/site-packages/rest_framework/serializers.py", line 234, in is_valid
    self._validated_data = self.run_validation(self.initial_data)
  File "/home/preetham/.local/lib/python3.8/site-packages/rest_framework/serializers.py", line 433, in run_validation
    value = self.to_internal_value(data)
  File "/home/preetham/.local/lib/python3.8/site-packages/rest_framework/serializers.py", line 490, in to_internal_value
    validated_value = field.run_validation(primitive_value)
  File "/home/preetham/.local/lib/python3.8/site-packages/rest_framework/fields.py", line 830, in run_validation
    return super().run_validation(data)
  File "/home/preetham/.local/lib/python3.8/site-packages/rest_framework/fields.py", line 566, in run_validation
    self.run_validators(value)
  File "/home/preetham/.local/lib/python3.8/site-packages/rest_framework/fields.py", line 588, in run_validators
    validator(value, self)
  File "/home/preetham/.local/lib/python3.8/site-packages/rest_framework/validators.py", line 73, in __call__
    if qs_exists(queryset):
  File "/home/preetham/.local/lib/python3.8/site-packages/rest_framework/validators.py", line 21, in qs_exists
    return queryset.exists()
  File "/home/preetham/.local/lib/python3.8/site-packages/django/db/models/query.py", line 892, in exists
    return self.query.has_results(using=self.db)
  File "/home/preetham/.local/lib/python3.8/site-packages/django/db/models/sql/query.py", line 589, in has_results
    return compiler.has_results()
  File "/home/preetham/.local/lib/python3.8/site-packages/django/db/models/sql/compiler.py", line 1329, in has_results
    return bool(self.execute_sql(SINGLE))
  File "/home/preetham/.local/lib/python3.8/site-packages/django/db/models/sql/compiler.py", line 1361, in execute_sql
    cursor.execute(sql, params)
  File "/home/preetham/.local/lib/python3.8/site-packages/django/db/backends/utils.py", line 103, in execute
    return super().execute(sql, params)
  File "/home/preetham/.local/lib/python3.8/site-packages/django/db/backends/utils.py", line 67, in execute
    return self._execute_with_wrappers(
  File "/home/preetham/.local/lib/python3.8/site-packages/django/db/backends/utils.py", line 80, in _execute_with_wrappers
    return executor(sql, params, many, context)
  File "/home/preetham/.local/lib/python3.8/site-packages/django/db/backends/utils.py", line 89, in _execute
    return self.cursor.execute(sql, params)
  File "/home/preetham/.local/lib/python3.8/site-packages/django/db/utils.py", line 91, in __exit__
    raise dj_exc_value.with_traceback(traceback) from exc_value
  File "/home/preetham/.local/lib/python3.8/site-packages/django/db/backends/utils.py", line 89, in _execute
    return self.cursor.execute(sql, params)
  File "/home/preetham/.local/lib/python3.8/site-packages/django/db/backends/mysql/base.py", line 75, in execute
    return self.cursor.execute(query, args)
  File "/home/preetham/.local/lib/python3.8/site-packages/MySQLdb/cursors.py", line 206, in execute
    res = self._query(query)
  File "/home/preetham/.local/lib/python3.8/site-packages/MySQLdb/cursors.py", line 319, in _query
    db.query(q)
  File "/home/preetham/.local/lib/python3.8/site-packages/MySQLdb/connections.py", line 254, in query
    _mysql.connection.query(self, query)
django.db.utils.ProgrammingError: (1146, "Table 'tododb.api_user' doesn't exist")
